Workbook
Name financialYear: 'Transaction details'!$G:$G
Name depnMethodAcc: 'Transaction details'!$J:$J
Name depnMethodTax: 'Transaction details'!$M:$M
Name assetClass: 'Transaction details'!$B:$B
Name accountingImpact: 'Transaction details'!$I:$I
Name effectiveDate: 'Transaction details'!$E:$E
Name depnRateAcc: 'Transaction details'!$K:$K
Name financialMonth: 'Transaction details'!$F:$F
Name assetLookUp: 'Transaction details'!$A:$A
Name transactionType: 'Transaction details'!$H:$H
Name depnRateTax: 'Transaction details'!$N:$N
Name taxImpact: 'Transaction details'!$L:$L

Sheet Transaction details
A1: Asset ID | B1: Asset category | C1: Asset description | D1: Record date | E1: Effective date | F1: Financial month | G1: Financial year | H1: Transaction type | I1: Transaction amount (acc) | J1: Depn method (acc) | K1: Depn rate (Acc) | L1: Transaction amount (tax) | M1: Depn method (tax) | N1: Depn rate (Tax)
A2: 00001 | B2: Land (freehold) | C2: New premises | D2: 45017 | E2: 45017 | F2: =if(isblank(E2),,if(month(E2)-3>0,month(E2)-3,month(E2)+9)) -> 1 | G2: =if(isblank(F2),,if(F2<10,year(E2)+1,year(E2))) -> 2024 | H2: Acquisition | I2: 5000000 | J2: Straight-line | L2: 5000000 | M2: Non-depreciable
A3: 00002 | B3: Building structure | C3: Building acquired as part of new premises | D3: 45017 | E3: 45017 | F3: =if(isblank(E3),,if(month(E3)-3>0,month(E3)-3,month(E3)+9)) -> 1 | G3: =if(isblank(F3),,if(F3<10,year(E3)+1,year(E3))) -> 2024 | H3: Acquisition | I3: 2000000 | J3: Straight-line | K3: 0.02 | L3: 2000000 | M3: Diminishing value | N3: 0
A4: 00003 | B4: Building fitout | C4: Fitout acquired as part of new premises | D4: 45017 | E4: 45017 | F4: =if(isblank(E4),,if(month(E4)-3>0,month(E4)-3,month(E4)+9)) -> 1 | G4: =if(isblank(F4),,if(F4<10,year(E4)+1,year(E4))) -> 2024 | H4: Acquisition | I4: 600000 | J4: Straight-line | K4: 0.2 | L4: 600000 | M4: Diminishing value | N4: 0.15
A5: 00004 | B5: Vehicles | C5: Honda Torneo 2002 (rego ABC123) | D5: 45107 | E5: 45105 | F5: =if(isblank(E5),,if(month(E5)-3>0,month(E5)-3,month(E5)+9)) -> 3 | G5: =if(isblank(F5),,if(F5<10,year(E5)+1,year(E5))) -> 2024 | H5: Acquisition | I5: 2500 | J5: Straight-line | K5: 0.3 | M5: Diminishing value | N5: 0.4
A6: 00005 | B6: Computer software | C6: Website costs capitalised for tax | D6: 45199 | E6: 45198 | F6: =if(isblank(E6),,if(month(E6)-3>0,month(E6)-3,month(E6)+9)) -> 6 | G6: =if(isblank(F6),,if(F6<10,year(E6)+1,year(E6))) -> 2024 | H6: Acquisition | L6: 16000 | M6: Diminishing value | N6: 0.6
A7: 00006 | B7: Plant and equipment | C7: iPhone 14 (serial XYZ123467) | D7: 45303 | E7: 45303 | F7: =if(isblank(E7),,if(month(E7)-3>0,month(E7)-3,month(E7)+9)) -> 10 | G7: =if(isblank(F7),,if(F7<10,year(E7)+1,year(E7))) -> 2024 | H7: Acquisition | I7: 800 | J7: Straight-line | K7: 0.5 | M7: Low-value write-off
F8: =if(isblank(E8),,if(month(E8)-3>0,month(E8)-3,month(E8)+9)) | G8: =if(isblank(F8),,if(F8<10,year(E8)+1,year(E8)))
F9: =if(isblank(E9),,if(month(E9)-3>0,month(E9)-3,month(E9)+9)) | G9: =if(isblank(F9),,if(F9<10,year(E9)+1,year(E9)))
F10: =if(isblank(E10),,if(month(E10)-3>0,month(E10)-3,month(E10)+9)) | G10: =if(isblank(F10),,if(F10<10,year(E10)+1,year(E10)))
F11: =if(isblank(E11),,if(month(E11)-3>0,month(E11)-3,month(E11)+9)) | G11: =if(isblank(F11),,if(F11<10,year(E11)+1,year(E11)))
F12: =if(isblank(E12),,if(month(E12)-3>0,month(E12)-3,month(E12)+9)) | G12: =if(isblank(F12),,if(F12<10,year(E12)+1,year(E12)))
F13: =if(isblank(E13),,if(month(E13)-3>0,month(E13)-3,month(E13)+9)) | G13: =if(isblank(F13),,if(F13<10,year(E13)+1,year(E13)))
F14: =if(isblank(E14),,if(month(E14)-3>0,month(E14)-3,month(E14)+9)) | G14: =if(isblank(F14),,if(F14<10,year(E14)+1,year(E14)))
F15: =if(isblank(E15),,if(month(E15)-3>0,month(E15)-3,month(E15)+9)) | G15: =if(isblank(F15),,if(F15<10,year(E15)+1,year(E15)))
F16: =if(isblank(E16),,if(month(E16)-3>0,month(E16)-3,month(E16)+9)) | G16: =if(isblank(F16),,if(F16<10,year(E16)+1,year(E16)))
F17: =if(isblank(E17),,if(month(E17)-3>0,month(E17)-3,month(E17)+9)) | G17: =if(isblank(F17),,if(F17<10,year(E17)+1,year(E17)))
F18: =if(isblank(E18),,if(month(E18)-3>0,month(E18)-3,month(E18)+9)) | G18: =if(isblank(F18),,if(F18<10,year(E18)+1,year(E18)))

Sheet Comments
A2: For accounting and tax reporting, businesses need to maintain a fixed asset register. Typically a business will have separate registers for tax and accounting.
A4: The register essentially records assets that a business owns and uses to generate income (ie, fixed assets). Fixed-assets can be contrasted with assets that are sold to generate income (ie, trading stock) and assets that are consumed (ie, consumables like petrol).
A6: Most people I've worked with face issues with their fixed-asset registers. The issues can range from: - poor data inputs and manual tracking of assets - incorrect formula to calculate depreciation - manual processes and spreadsheets with high liklihood for error - using software which lacks the features necessary for their business (eg, cannot load revaluations) - how errors are corrected when they are identified The challenge with maintaining a healthy fixed-asset register is compounded by the fact that each year's register is built off of prior years, meaning issues can compound over multiple years and blow up. | G6: wizard on boarding process, mobile app walkthrough. does the user need to see the depreciation calulated straight away or does that feed to us first to review? object history, ood, historical and forward looking per object in current depreciation method, retains information on changes in depreciation model when updated.
A8: There are already a number of technological solutions. Eg, - Barcode / QR tagging your fixed-assets to make stocktaking easier - Using AI to review asset classifications and depreciation rates based on available descriptions | G8: can combine with test and tag
A10: I think there is still scope for massive improvement in fixed-asset tracking. I think the gold-standard for maintaining a fixed-asset reigster is to keep a record/ledger of transactions that feeds into the fixed asset registers. In my view, users should not be allowed to get into the calculations themselves because that is where the majority of errors occur. We should be able to design a tool/platform where people have all the control they need over the calculations by simply recording new transactions. Eg, if an asset is unavailable to be used for three months of the year that should be recorded as one or more transaction. The effect will be that from the time the asset is unavailable for use, it will not be depreciated. Once the asset becomes available for use again, the depreciation should restart. | G10: oodb is the ledger
A12: A record of transactions made in a financial year should be far easier for management to review than attempting to review the full fixed-asset register for the year. Because the transaction list is easier to review/audit, it should be easier for management and their advisors to identify data input issues and correct these. By having an audit trail of transactions we should also be able to subsequently correct errors. Eg, it should be possible to select one or more transactions from the past and propose a "correction" to them. Our system could then generate the current period adjustments necessary to bring the fixed asset register back to the position it would have been, if the correct inputs had been loaded originally.

Sheet FY24 working
A1: Year | B1: 2024 | C1: 2024 | D1: 2024 | E1: 2024 | F1: 2024 | G1: 2024 | H1: 2024 | I1: 2024 | J1: 2024 | K1: 2024 | L1: 2024 | M1: 2024 | N1: 2024 | O1: 2024 | P1: 2024 | Q1: 2024 | R1: 2024 | S1: 2024 | T1: 2024 | U1: 2024 | V1: 2024 | W1: 2024 | X1: 2024 | Y1: 2024 | Z1: 2024 | AA1: 2024 | AB1: 2024 | AC1: 2024 | AD1: 2024 | AE1: 2024 | AF1: 2024 | AG1: 2024 | AH1: 2024 | AI1: 2024 | AJ1: 2024 | AK1: 2024 | AL1: 2024 | AM1: 2024 | AN1: 2024 | AO1: 2024 | AP1: 2024 | AQ1: 2024 | AR1: 2024 | AS1: 2024 | AT1: 2024 | AU1: 2024 | AV1: 2024 | AW1: 2024 | AX1: 2024 | AY1: 2024 | AZ1: 2024 | BA1: 2024 | BB1: 2024 | BC1: 2024 | BD1: 2024 | BE1: 2024 | BF1: 2024 | BG1: 2024 | BH1: 2024 | BI1: 2024
A2: Month | B2: 1 | C2: 1 | D2: 1 | E2: 1 | F2: 1 | G2: 2 | H2: 2 | I2: 2 | J2: 2 | K2: 2 | L2: 3 | M2: 3 | N2: 3 | O2: 3 | P2: 3 | Q2: 4 | R2: 4 | S2: 4 | T2: 4 | U2: 4 | V2: 5 | W2: 5 | X2: 5 | Y2: 5 | Z2: 5 | AA2: 6 | AB2: 6 | AC2: 6 | AD2: 6 | AE2: 6 | AF2: 7 | AG2: 7 | AH2: 7 | AI2: 7 | AJ2: 7 | AK2: 8 | AL2: 8 | AM2: 8 | AN2: 8 | AO2: 8 | AP2: 9 | AQ2: 9 | AR2: 9 | AS2: 9 | AT2: 9 | AU2: 10 | AV2: 10 | AW2: 10 | AX2: 10 | AY2: 10 | AZ2: 11 | BA2: 11 | BB2: 11 | BC2: 11 | BD2: 11 | BE2: 12 | BF2: 12 | BG2: 12 | BH2: 12 | BI2: 12
A3: Assets | B3: Month One | G3: Month Two | L3: Month Three | Q3: Month Four | V3: Month Five | AA3: Month Six | AF3: Month Seven | AK3: Month Eight | AP3: Month Nine | AU3: Month Ten | AZ3: Month Eleven | BE3: Month Twelve | BJ3: Acc classification at close
B4: Opening value | C4: Revalns | D4: Acquisitions | E4: Disposals | F4: Depn | G4: Opening value | H4: Revalns | I4: Acquisitions | J4: Disposals | K4: Depn | L4: Opening value | M4: Revalns | N4: Acquisitions | O4: Disposals | P4: Depn | Q4: Opening value | R4: Revalns | S4: Acquisitions | T4: Disposals | U4: Depn | V4: Opening value | W4: Revalns | X4: Acquisitions | Y4: Disposals | Z4: Depn | AA4: Opening value | AB4: Revalns | AC4: Acquisitions | AD4: Disposals | AE4: Depn | AF4: Opening value | AG4: Revalns | AH4: Acquisitions | AI4: Disposals | AJ4: Depn | AK4: Opening value | AL4: Revalns | AM4: Acquisitions | AN4: Disposals | AO4: Depn | AP4: Opening value | AQ4: Revalns | AR4: Acquisitions | AS4: Disposals | AT4: Depn | AU4: Opening value | AV4: Revalns | AW4: Acquisitions | AX4: Disposals | AY4: Depn | AZ4: Opening value | BA4: Revalns | BB4: Acquisitions | BC4: Disposals | BD4: Depn | BE4: Opening value | BF4: Revalns | BG4: Acquisitions | BH4: Disposals | BI4: Depn | BK4: Open | BL4: Total revals | BM4: Total additions | BN4: Total disposals | BO4: Total depn | BP4: Close
A5: 00001 | B5: 0 | C5: =sumifs(accountingImpact,assetLookUp,$A5,financialMonth,C$2,financialYear,C$1,transactionType,"Revaluation") -> 0 | D5: =sumifs(accountingImpact,assetLookUp,$A5,financialMonth,C$2,financialYear,C$1,transactionType,"Acquisition") -> 5000000 | E5: =sumifs(accountingImpact,assetLookUp,$A5,financialMonth,C$2,financialYear,C$1,transactionType,"Disposal") -> 0 | F5: {=-sum(B5:E5)*index(depnRateAcc,match($A5,assetLookUp,0),)} -> 0 | G5: =sum(B5:F5) -> 5000000 | H5: =sumifs(accountingImpact,assetLookUp,$A5,financialMonth,H$2,financialYear,H$1,transactionType,"Revaluation") -> 0 | I5: =sumifs(accountingImpact,assetLookUp,$A5,financialMonth,H$2,financialYear,H$1,transactionType,"Acquisition") -> 0 | J5: =sumifs(accountingImpact,assetLookUp,$A5,financialMonth,H$2,financialYear,H$1,transactionType,"Disposal") -> 0 | K5: {=-sum(G5:J5)*index(depnRateAcc,match($A5,assetLookUp,0),)} -> 0 | L5: =sum(G5:K5) -> 5000000 | M5: =sumifs(accountingImpact,assetLookUp,$A5,financialMonth,M$2,financialYear,M$1,transactionType,"Revaluation") -> 0 | N5: =sumifs(accountingImpact,assetLookUp,$A5,financialMonth,M$2,financialYear,M$1,transactionType,"Acquisition") -> 0 | O5: =sumifs(accountingImpact,assetLookUp,$A5,financialMonth,M$2,financialYear,M$1,transactionType,"Disposal") -> 0 | P5: {=-sum(L5:O5)*index(depnRateAcc,match($A5,assetLookUp,0),)} -> 0 | Q5: =sum(L5:P5) -> 5000000 | R5: =sumifs(accountingImpact,assetLookUp,$A5,financialMonth,R$2,financialYear,R$1,transactionType,"Revaluation") -> 0 | S5: =sumifs(accountingImpact,assetLookUp,$A5,financialMonth,R$2,financialYear,R$1,transactionType,"Acquisition") -> 0 | T5: =sumifs(accountingImpact,assetLookUp,$A5,financialMonth,R$2,financialYear,R$1,transactionType,"Disposal") -> 0 | U5: {=-sum(Q5:T5)*index(depnRateAcc,match($A5,assetLookUp,0),)} -> 0 | V5: =sum(Q5:U5) -> 5000000 | W5: =sumifs(accountingImpact,assetLookUp,$A5,financialMonth,W$2,financialYear,W$1,transactionType,"Revaluation") -> 0 | X5: =sumifs(accountingImpact,assetLookUp,$A5,financialMonth,W$2,financialYear,W$1,transactionType,"Acquisition") -> 0 | Y5: =sumifs(accountingImpact,assetLookUp,$A5,financialMonth,W$2,financialYear,W$1,transactionType,"Disposal") -> 0 | Z5: {=-sum(V5:Y5)*index(depnRateAcc,match($A5,assetLookUp,0),)} -> 0 | AA5: =sum(V5:Z5) -> 5000000 | AB5: =sumifs(accountingImpact,assetLookUp,$A5,financialMonth,AB$2,financialYear,AB$1,transactionType,"Revaluation") -> 0 | AC5: =sumifs(accountingImpact,assetLookUp,$A5,financialMonth,AB$2,financialYear,AB$1,transactionType,"Acquisition") -> 0 | AD5: =sumifs(accountingImpact,assetLookUp,$A5,financialMonth,AB$2,financialYear,AB$1,transactionType,"Disposal") -> 0 | AE5: {=-sum(AA5:AD5)*index(depnRateAcc,match($A5,assetLookUp,0),)} -> 0 | AF5: =sum(AA5:AE5) -> 5000000 | AG5: =sumifs(accountingImpact,assetLookUp,$A5,financialMonth,AG$2,financialYear,AG$1,transactionType,"Revaluation") -> 0 | AH5: =sumifs(accountingImpact,assetLookUp,$A5,financialMonth,AG$2,financialYear,AG$1,transactionType,"Acquisition") -> 0 | AI5: =sumifs(accountingImpact,assetLookUp,$A5,financialMonth,AG$2,financialYear,AG$1,transactionType,"Disposal") -> 0 | AJ5: {=-sum(AF5:AI5)*index(depnRateAcc,match($A5,assetLookUp,0),)} -> 0 | AK5: =sum(AF5:AJ5) -> 5000000 | AL5: =sumifs(accountingImpact,assetLookUp,$A5,financialMonth,AL$2,financialYear,AL$1,transactionType,"Revaluation") -> 0 | AM5: =sumifs(accountingImpact,assetLookUp,$A5,financialMonth,AL$2,financialYear,AL$1,transactionType,"Acquisition") -> 0 | AN5: =sumifs(accountingImpact,assetLookUp,$A5,financialMonth,AL$2,financialYear,AL$1,transactionType,"Disposal") -> 0 | AO5: {=-sum(AK5:AN5)*index(depnRateAcc,match($A5,assetLookUp,0),)} -> 0 | AP5: =sum(AK5:AO5) -> 5000000 | AQ5: =sumifs(accountingImpact,assetLookUp,$A5,financialMonth,AQ$2,financialYear,AQ$1,transactionType,"Revaluation") -> 0 | AR5: =sumifs(accountingImpact,assetLookUp,$A5,financialMonth,AQ$2,financialYear,AQ$1,transactionType,"Acquisition") -> 0 | AS5: =sumifs(accountingImpact,assetLookUp,$A5,financialMonth,AQ$2,financialYear,AQ$1,transactionType,"Disposal") -> 0 | AT5: {=-sum(AP5:AS5)*index(depnRateAcc,match($A5,assetLookUp,0),)} -> 0 | AU5: =sum(AP5:AT5) -> 5000000 | AV5: =sumifs(accountingImpact,assetLookUp,$A5,financialMonth,AV$2,financialYear,AV$1,transactionType,"Revaluation") -> 0 | AW5: =sumifs(accountingImpact,assetLookUp,$A5,financialMonth,AV$2,financialYear,AV$1,transactionType,"Acquisition") -> 0 | AX5: =sumifs(accountingImpact,assetLookUp,$A5,financialMonth,AV$2,financialYear,AV$1,transactionType,"Disposal") -> 0 | AY5: {=-sum(AU5:AX5)*index(depnRateAcc,match($A5,assetLookUp,0),)} -> 0 | AZ5: =sum(AU5:AY5) -> 5000000 | BA5: =sumifs(accountingImpact,assetLookUp,$A5,financialMonth,BA$2,financialYear,BA$1,transactionType,"Revaluation") -> 0 | BB5: =sumifs(accountingImpact,assetLookUp,$A5,financialMonth,BA$2,financialYear,BA$1,transactionType,"Acquisition") -> 0 | BC5: =sumifs(accountingImpact,assetLookUp,$A5,financialMonth,BA$2,financialYear,BA$1,transactionType,"Disposal") -> 0 | BD5: {=-sum(AZ5:BC5)*index(depnRateAcc,match($A5,assetLookUp,0),)} -> 0 | BE5: =sum(AZ5:BD5) -> 5000000 | BF5: =sumifs(accountingImpact,assetLookUp,$A5,financialMonth,BF$2,financialYear,BF$1,transactionType,"Revaluation") -> 0 | BG5: =sumifs(accountingImpact,assetLookUp,$A5,financialMonth,BF$2,financialYear,BF$1,transactionType,"Acquisition") -> 0 | BH5: =sumifs(accountingImpact,assetLookUp,$A5,financialMonth,BF$2,financialYear,BF$1,transactionType,"Disposal") -> 0 | BI5: {=-sum(BE5:BH5)*index(depnRateAcc,match($A5,assetLookUp,0),)} -> 0 | BJ5: {=index(assetClass,match($A5,assetLookUp,0))} -> Land (freehold) | BK5: =B5 -> 0 | BL5: =sumif($B$4:$BI$4,"Revalns",$B5:$BI5) -> 0 | BM5: =sumif($B$4:$BI$4,"Acquisitions",$B5:$BI5) -> 5000000 | BN5: =sumif($B$4:$BI$4,"Disposals",$B5:$BI5) -> 0 | BO5: =sumif($B$4:$BI$4,"Depn",$B5:$BI5) -> 0 | BP5: =sum(BK5:BO5) -> 5000000
A6: 00002 | B6: 0 | C6: =sumifs(accountingImpact,assetLookUp,$A6,financialMonth,C$2,financialYear,C$1,transactionType,"Revaluation") -> 0 | D6: =sumifs(accountingImpact,assetLookUp,$A6,financialMonth,C$2,financialYear,C$1,transactionType,"Acquisition") -> 2000000 | E6: =sumifs(accountingImpact,assetLookUp,$A6,financialMonth,C$2,financialYear,C$1,transactionType,"Disposal") -> 0 | F6: {=-sum(B6:E6)*index(depnRateAcc,match($A6,assetLookUp,0),)} -> -40000 | G6: =sum(B6:F6) -> 1960000 | H6: =sumifs(accountingImpact,assetLookUp,$A6,financialMonth,H$2,financialYear,H$1,transactionType,"Revaluation") -> 0 | I6: =sumifs(accountingImpact,assetLookUp,$A6,financialMonth,H$2,financialYear,H$1,transactionType,"Acquisition") -> 0 | J6: =sumifs(accountingImpact,assetLookUp,$A6,financialMonth,H$2,financialYear,H$1,transactionType,"Disposal") -> 0 | K6: {=-sum(G6:J6)*index(depnRateAcc,match($A6,assetLookUp,0),)} -> -39200 | L6: =sum(G6:K6) -> 1920800 | M6: =sumifs(accountingImpact,assetLookUp,$A6,financialMonth,M$2,financialYear,M$1,transactionType,"Revaluation") -> 0 | N6: =sumifs(accountingImpact,assetLookUp,$A6,financialMonth,M$2,financialYear,M$1,transactionType,"Acquisition") -> 0 | O6: =sumifs(accountingImpact,assetLookUp,$A6,financialMonth,M$2,financialYear,M$1,transactionType,"Disposal") -> 0 | P6: {=-sum(L6:O6)*index(depnRateAcc,match($A6,assetLookUp,0),)} -> -38416 | Q6: =sum(L6:P6) -> 1882384 | R6: =sumifs(accountingImpact,assetLookUp,$A6,financialMonth,R$2,financialYear,R$1,transactionType,"Revaluation") -> 0 | S6: =sumifs(accountingImpact,assetLookUp,$A6,financialMonth,R$2,financialYear,R$1,transactionType,"Acquisition") -> 0 | T6: =sumifs(accountingImpact,assetLookUp,$A6,financialMonth,R$2,financialYear,R$1,transactionType,"Disposal") -> 0 | U6: {=-sum(Q6:T6)*index(depnRateAcc,match($A6,assetLookUp,0),)} -> -37647.68 | V6: =sum(Q6:U6) -> 1844736.3 | W6: =sumifs(accountingImpact,assetLookUp,$A6,financialMonth,W$2,financialYear,W$1,transactionType,"Revaluation") -> 0 | X6: =sumifs(accountingImpact,assetLookUp,$A6,financialMonth,W$2,financialYear,W$1,transactionType,"Acquisition") -> 0 | Y6: =sumifs(accountingImpact,assetLookUp,$A6,financialMonth,W$2,financialYear,W$1,transactionType,"Disposal") -> 0 | Z6: {=-sum(V6:Y6)*index(depnRateAcc,match($A6,assetLookUp,0),)} -> -36894.726 | AA6: =sum(V6:Z6) -> 1807841.6 | AB6: =sumifs(accountingImpact,assetLookUp,$A6,financialMonth,AB$2,financialYear,AB$1,transactionType,"Revaluation") -> 0 | AC6: =sumifs(accountingImpact,assetLookUp,$A6,financialMonth,AB$2,financialYear,AB$1,transactionType,"Acquisition") -> 0 | AD6: =sumifs(accountingImpact,assetLookUp,$A6,financialMonth,AB$2,financialYear,AB$1,transactionType,"Disposal") -> 0 | AE6: {=-sum(AA6:AD6)*index(depnRateAcc,match($A6,assetLookUp,0),)} -> -36156.832 | AF6: =sum(AA6:AE6) -> 1771684.8 | AG6: =sumifs(accountingImpact,assetLookUp,$A6,financialMonth,AG$2,financialYear,AG$1,transactionType,"Revaluation") -> 0 | AH6: =sumifs(accountingImpact,assetLookUp,$A6,financialMonth,AG$2,financialYear,AG$1,transactionType,"Acquisition") -> 0 | AI6: =sumifs(accountingImpact,assetLookUp,$A6,financialMonth,AG$2,financialYear,AG$1,transactionType,"Disposal") -> 0 | AJ6: {=-sum(AF6:AI6)*index(depnRateAcc,match($A6,assetLookUp,0),)} -> -35433.695 | AK6: =sum(AF6:AJ6) -> 1736251.1 | AL6: =sumifs(accountingImpact,assetLookUp,$A6,financialMonth,AL$2,financialYear,AL$1,transactionType,"Revaluation") -> 0 | AM6: =sumifs(accountingImpact,assetLookUp,$A6,financialMonth,AL$2,financialYear,AL$1,transactionType,"Acquisition") -> 0 | AN6: =sumifs(accountingImpact,assetLookUp,$A6,financialMonth,AL$2,financialYear,AL$1,transactionType,"Disposal") -> 0 | AO6: {=-sum(AK6:AN6)*index(depnRateAcc,match($A6,assetLookUp,0),)} -> -34725.021 | AP6: =sum(AK6:AO6) -> 1701526 | AQ6: =sumifs(accountingImpact,assetLookUp,$A6,financialMonth,AQ$2,financialYear,AQ$1,transactionType,"Revaluation") -> 0 | AR6: =sumifs(accountingImpact,assetLookUp,$A6,financialMonth,AQ$2,financialYear,AQ$1,transactionType,"Acquisition") -> 0 | AS6: =sumifs(accountingImpact,assetLookUp,$A6,financialMonth,AQ$2,financialYear,AQ$1,transactionType,"Disposal") -> 0 | AT6: {=-sum(AP6:AS6)*index(depnRateAcc,match($A6,assetLookUp,0),)} -> -34030.521 | AU6: =sum(AP6:AT6) -> 1667495.5 | AV6: =sumifs(accountingImpact,assetLookUp,$A6,financialMonth,AV$2,financialYear,AV$1,transactionType,"Revaluation") -> 0 | AW6: =sumifs(accountingImpact,assetLookUp,$A6,financialMonth,AV$2,financialYear,AV$1,transactionType,"Acquisition") -> 0 | AX6: =sumifs(accountingImpact,assetLookUp,$A6,financialMonth,AV$2,financialYear,AV$1,transactionType,"Disposal") -> 0 | AY6: {=-sum(AU6:AX6)*index(depnRateAcc,match($A6,assetLookUp,0),)} -> -33349.91 | AZ6: =sum(AU6:AY6) -> 1634145.6 | BA6: =sumifs(accountingImpact,assetLookUp,$A6,financialMonth,BA$2,financialYear,BA$1,transactionType,"Revaluation") -> 0 | BB6: =sumifs(accountingImpact,assetLookUp,$A6,financialMonth,BA$2,financialYear,BA$1,transactionType,"Acquisition") -> 0 | BC6: =sumifs(accountingImpact,assetLookUp,$A6,financialMonth,BA$2,financialYear,BA$1,transactionType,"Disposal") -> 0 | BD6: {=-sum(AZ6:BC6)*index(depnRateAcc,match($A6,assetLookUp,0),)} -> -32682.912 | BE6: =sum(AZ6:BD6) -> 1601462.7 | BF6: =sumifs(accountingImpact,assetLookUp,$A6,financialMonth,BF$2,financialYear,BF$1,transactionType,"Revaluation") -> 0 | BG6: =sumifs(accountingImpact,assetLookUp,$A6,financialMonth,BF$2,financialYear,BF$1,transactionType,"Acquisition") -> 0 | BH6: =sumifs(accountingImpact,assetLookUp,$A6,financialMonth,BF$2,financialYear,BF$1,transactionType,"Disposal") -> 0 | BI6: {=-sum(BE6:BH6)*index(depnRateAcc,match($A6,assetLookUp,0),)} -> -32029.254 | BJ6: {=index(assetClass,match($A6,assetLookUp,0))} -> Building structure | BK6: =B6 -> 0 | BL6: =sumif($B$4:$BI$4,"Revalns",$B6:$BI6) -> 0 | BM6: =sumif($B$4:$BI$4,"Acquisitions",$B6:$BI6) -> 2000000 | BN6: =sumif($B$4:$BI$4,"Disposals",$B6:$BI6) -> 0 | BO6: =sumif($B$4:$BI$4,"Depn",$B6:$BI6) -> -430566.55 | BP6: =sum(BK6:BO6) -> 1569433.4
A7: 00003 | B7: 0 | C7: =sumifs(accountingImpact,assetLookUp,$A7,financialMonth,C$2,financialYear,C$1,transactionType,"Revaluation") -> 0 | D7: =sumifs(accountingImpact,assetLookUp,$A7,financialMonth,C$2,financialYear,C$1,transactionType,"Acquisition") -> 600000 | E7: =sumifs(accountingImpact,assetLookUp,$A7,financialMonth,C$2,financialYear,C$1,transactionType,"Disposal") -> 0 | F7: {=-sum(B7:E7)*index(depnRateAcc,match($A7,assetLookUp,0),)} -> -120000 | G7: =sum(B7:F7) -> 480000 | H7: =sumifs(accountingImpact,assetLookUp,$A7,financialMonth,H$2,financialYear,H$1,transactionType,"Revaluation") -> 0 | I7: =sumifs(accountingImpact,assetLookUp,$A7,financialMonth,H$2,financialYear,H$1,transactionType,"Acquisition") -> 0 | J7: =sumifs(accountingImpact,assetLookUp,$A7,financialMonth,H$2,financialYear,H$1,transactionType,"Disposal") -> 0 | K7: {=-sum(G7:J7)*index(depnRateAcc,match($A7,assetLookUp,0),)} -> -96000 | L7: =sum(G7:K7) -> 384000 | M7: =sumifs(accountingImpact,assetLookUp,$A7,financialMonth,M$2,financialYear,M$1,transactionType,"Revaluation") -> 0 | N7: =sumifs(accountingImpact,assetLookUp,$A7,financialMonth,M$2,financialYear,M$1,transactionType,"Acquisition") -> 0 | O7: =sumifs(accountingImpact,assetLookUp,$A7,financialMonth,M$2,financialYear,M$1,transactionType,"Disposal") -> 0 | P7: {=-sum(L7:O7)*index(depnRateAcc,match($A7,assetLookUp,0),)} -> -76800 | Q7: =sum(L7:P7) -> 307200 | R7: =sumifs(accountingImpact,assetLookUp,$A7,financialMonth,R$2,financialYear,R$1,transactionType,"Revaluation") -> 0 | S7: =sumifs(accountingImpact,assetLookUp,$A7,financialMonth,R$2,financialYear,R$1,transactionType,"Acquisition") -> 0 | T7: =sumifs(accountingImpact,assetLookUp,$A7,financialMonth,R$2,financialYear,R$1,transactionType,"Disposal") -> 0 | U7: {=-sum(Q7:T7)*index(depnRateAcc,match($A7,assetLookUp,0),)} -> -61440 | V7: =sum(Q7:U7) -> 245760 | W7: =sumifs(accountingImpact,assetLookUp,$A7,financialMonth,W$2,financialYear,W$1,transactionType,"Revaluation") -> 0 | X7: =sumifs(accountingImpact,assetLookUp,$A7,financialMonth,W$2,financialYear,W$1,transactionType,"Acquisition") -> 0 | Y7: =sumifs(accountingImpact,assetLookUp,$A7,financialMonth,W$2,financialYear,W$1,transactionType,"Disposal") -> 0 | Z7: {=-sum(V7:Y7)*index(depnRateAcc,match($A7,assetLookUp,0),)} -> -49152 | AA7: =sum(V7:Z7) -> 196608 | AB7: =sumifs(accountingImpact,assetLookUp,$A7,financialMonth,AB$2,financialYear,AB$1,transactionType,"Revaluation") -> 0 | AC7: =sumifs(accountingImpact,assetLookUp,$A7,financialMonth,AB$2,financialYear,AB$1,transactionType,"Acquisition") -> 0 | AD7: =sumifs(accountingImpact,assetLookUp,$A7,financialMonth,AB$2,financialYear,AB$1,transactionType,"Disposal") -> 0 | AE7: {=-sum(AA7:AD7)*index(depnRateAcc,match($A7,assetLookUp,0),)} -> -39321.6 | AF7: =sum(AA7:AE7) -> 157286.4 | AG7: =sumifs(accountingImpact,assetLookUp,$A7,financialMonth,AG$2,financialYear,AG$1,transactionType,"Revaluation") -> 0 | AH7: =sumifs(accountingImpact,assetLookUp,$A7,financialMonth,AG$2,financialYear,AG$1,transactionType,"Acquisition") -> 0 | AI7: =sumifs(accountingImpact,assetLookUp,$A7,financialMonth,AG$2,financialYear,AG$1,transactionType,"Disposal") -> 0 | AJ7: {=-sum(AF7:AI7)*index(depnRateAcc,match($A7,assetLookUp,0),)} -> -31457.28 | AK7: =sum(AF7:AJ7) -> 125829.12 | AL7: =sumifs(accountingImpact,assetLookUp,$A7,financialMonth,AL$2,financialYear,AL$1,transactionType,"Revaluation") -> 0 | AM7: =sumifs(accountingImpact,assetLookUp,$A7,financialMonth,AL$2,financialYear,AL$1,transactionType,"Acquisition") -> 0 | AN7: =sumifs(accountingImpact,assetLookUp,$A7,financialMonth,AL$2,financialYear,AL$1,transactionType,"Disposal") -> 0 | AO7: {=-sum(AK7:AN7)*index(depnRateAcc,match($A7,assetLookUp,0),)} -> -25165.824 | AP7: =sum(AK7:AO7) -> 100663.3 | AQ7: =sumifs(accountingImpact,assetLookUp,$A7,financialMonth,AQ$2,financialYear,AQ$1,transactionType,"Revaluation") -> 0 | AR7: =sumifs(accountingImpact,assetLookUp,$A7,financialMonth,AQ$2,financialYear,AQ$1,transactionType,"Acquisition") -> 0 | AS7: =sumifs(accountingImpact,assetLookUp,$A7,financialMonth,AQ$2,financialYear,AQ$1,transactionType,"Disposal") -> 0 | AT7: {=-sum(AP7:AS7)*index(depnRateAcc,match($A7,assetLookUp,0),)} -> -20132.659 | AU7: =sum(AP7:AT7) -> 80530.637 | AV7: =sumifs(accountingImpact,assetLookUp,$A7,financialMonth,AV$2,financialYear,AV$1,transactionType,"Revaluation") -> 0 | AW7: =sumifs(accountingImpact,assetLookUp,$A7,financialMonth,AV$2,financialYear,AV$1,transactionType,"Acquisition") -> 0 | AX7: =sumifs(accountingImpact,assetLookUp,$A7,financialMonth,AV$2,financialYear,AV$1,transactionType,"Disposal") -> 0 | AY7: {=-sum(AU7:AX7)*index(depnRateAcc,match($A7,assetLookUp,0),)} -> -16106.127 | AZ7: =sum(AU7:AY7) -> 64424.509 | BA7: =sumifs(accountingImpact,assetLookUp,$A7,financialMonth,BA$2,financialYear,BA$1,transactionType,"Revaluation") -> 0 | BB7: =sumifs(accountingImpact,assetLookUp,$A7,financialMonth,BA$2,financialYear,BA$1,transactionType,"Acquisition") -> 0 | BC7: =sumifs(accountingImpact,assetLookUp,$A7,financialMonth,BA$2,financialYear,BA$1,transactionType,"Disposal") -> 0 | BD7: {=-sum(AZ7:BC7)*index(depnRateAcc,match($A7,assetLookUp,0),)} -> -12884.902 | BE7: =sum(AZ7:BD7) -> 51539.608 | BF7: =sumifs(accountingImpact,assetLookUp,$A7,financialMonth,BF$2,financialYear,BF$1,transactionType,"Revaluation") -> 0 | BG7: =sumifs(accountingImpact,assetLookUp,$A7,financialMonth,BF$2,financialYear,BF$1,transactionType,"Acquisition") -> 0 | BH7: =sumifs(accountingImpact,assetLookUp,$A7,financialMonth,BF$2,financialYear,BF$1,transactionType,"Disposal") -> 0 | BI7: {=-sum(BE7:BH7)*index(depnRateAcc,match($A7,assetLookUp,0),)} -> -10307.922 | BJ7: {=index(assetClass,match($A7,assetLookUp,0))} -> Building fitout | BK7: =B7 -> 0 | BL7: =sumif($B$4:$BI$4,"Revalns",$B7:$BI7) -> 0 | BM7: =sumif($B$4:$BI$4,"Acquisitions",$B7:$BI7) -> 600000 | BN7: =sumif($B$4:$BI$4,"Disposals",$B7:$BI7) -> 0 | BO7: =sumif($B$4:$BI$4,"Depn",$B7:$BI7) -> -558768.31 | BP7: =sum(BK7:BO7) -> 41231.686
A8: 00004 | B8: 0 | C8: =sumifs(accountingImpact,assetLookUp,$A8,financialMonth,C$2,financialYear,C$1,transactionType,"Revaluation") -> 0 | D8: =sumifs(accountingImpact,assetLookUp,$A8,financialMonth,C$2,financialYear,C$1,transactionType,"Acquisition") -> 0 | E8: =sumifs(accountingImpact,assetLookUp,$A8,financialMonth,C$2,financialYear,C$1,transactionType,"Disposal") -> 0 | F8: {=-sum(B8:E8)*index(depnRateAcc,match($A8,assetLookUp,0),)} -> 0 | G8: =sum(B8:F8) -> 0 | H8: =sumifs(accountingImpact,assetLookUp,$A8,financialMonth,H$2,financialYear,H$1,transactionType,"Revaluation") -> 0 | I8: =sumifs(accountingImpact,assetLookUp,$A8,financialMonth,H$2,financialYear,H$1,transactionType,"Acquisition") -> 0 | J8: =sumifs(accountingImpact,assetLookUp,$A8,financialMonth,H$2,financialYear,H$1,transactionType,"Disposal") -> 0 | K8: {=-sum(G8:J8)*index(depnRateAcc,match($A8,assetLookUp,0),)} -> 0 | L8: =sum(G8:K8) -> 0 | M8: =sumifs(accountingImpact,assetLookUp,$A8,financialMonth,M$2,financialYear,M$1,transactionType,"Revaluation") -> 0 | N8: =sumifs(accountingImpact,assetLookUp,$A8,financialMonth,M$2,financialYear,M$1,transactionType,"Acquisition") -> 2500 | O8: =sumifs(accountingImpact,assetLookUp,$A8,financialMonth,M$2,financialYear,M$1,transactionType,"Disposal") -> 0 | P8: {=-sum(L8:O8)*index(depnRateAcc,match($A8,assetLookUp,0),)} -> -750 | Q8: =sum(L8:P8) -> 1750 | R8: =sumifs(accountingImpact,assetLookUp,$A8,financialMonth,R$2,financialYear,R$1,transactionType,"Revaluation") -> 0 | S8: =sumifs(accountingImpact,assetLookUp,$A8,financialMonth,R$2,financialYear,R$1,transactionType,"Acquisition") -> 0 | T8: =sumifs(accountingImpact,assetLookUp,$A8,financialMonth,R$2,financialYear,R$1,transactionType,"Disposal") -> 0 | U8: {=-sum(Q8:T8)*index(depnRateAcc,match($A8,assetLookUp,0),)} -> -525 | V8: =sum(Q8:U8) -> 1225 | W8: =sumifs(accountingImpact,assetLookUp,$A8,financialMonth,W$2,financialYear,W$1,transactionType,"Revaluation") -> 0 | X8: =sumifs(accountingImpact,assetLookUp,$A8,financialMonth,W$2,financialYear,W$1,transactionType,"Acquisition") -> 0 | Y8: =sumifs(accountingImpact,assetLookUp,$A8,financialMonth,W$2,financialYear,W$1,transactionType,"Disposal") -> 0 | Z8: {=-sum(V8:Y8)*index(depnRateAcc,match($A8,assetLookUp,0),)} -> -367.5 | AA8: =sum(V8:Z8) -> 857.5 | AB8: =sumifs(accountingImpact,assetLookUp,$A8,financialMonth,AB$2,financialYear,AB$1,transactionType,"Revaluation") -> 0 | AC8: =sumifs(accountingImpact,assetLookUp,$A8,financialMonth,AB$2,financialYear,AB$1,transactionType,"Acquisition") -> 0 | AD8: =sumifs(accountingImpact,assetLookUp,$A8,financialMonth,AB$2,financialYear,AB$1,transactionType,"Disposal") -> 0 | AE8: {=-sum(AA8:AD8)*index(depnRateAcc,match($A8,assetLookUp,0),)} -> -257.25 | AF8: =sum(AA8:AE8) -> 600.25 | AG8: =sumifs(accountingImpact,assetLookUp,$A8,financialMonth,AG$2,financialYear,AG$1,transactionType,"Revaluation") -> 0 | AH8: =sumifs(accountingImpact,assetLookUp,$A8,financialMonth,AG$2,financialYear,AG$1,transactionType,"Acquisition") -> 0 | AI8: =sumifs(accountingImpact,assetLookUp,$A8,financialMonth,AG$2,financialYear,AG$1,transactionType,"Disposal") -> 0 | AJ8: {=-sum(AF8:AI8)*index(depnRateAcc,match($A8,assetLookUp,0),)} -> -180.075 | AK8: =sum(AF8:AJ8) -> 420.175 | AL8: =sumifs(accountingImpact,assetLookUp,$A8,financialMonth,AL$2,financialYear,AL$1,transactionType,"Revaluation") -> 0 | AM8: =sumifs(accountingImpact,assetLookUp,$A8,financialMonth,AL$2,financialYear,AL$1,transactionType,"Acquisition") -> 0 | AN8: =sumifs(accountingImpact,assetLookUp,$A8,financialMonth,AL$2,financialYear,AL$1,transactionType,"Disposal") -> 0 | AO8: {=-sum(AK8:AN8)*index(depnRateAcc,match($A8,assetLookUp,0),)} -> -126.0525 | AP8: =sum(AK8:AO8) -> 294.1225 | AQ8: =sumifs(accountingImpact,assetLookUp,$A8,financialMonth,AQ$2,financialYear,AQ$1,transactionType,"Revaluation") -> 0 | AR8: =sumifs(accountingImpact,assetLookUp,$A8,financialMonth,AQ$2,financialYear,AQ$1,transactionType,"Acquisition") -> 0 | AS8: =sumifs(accountingImpact,assetLookUp,$A8,financialMonth,AQ$2,financialYear,AQ$1,transactionType,"Disposal") -> 0 | AT8: {=-sum(AP8:AS8)*index(depnRateAcc,match($A8,assetLookUp,0),)} -> -88.23675 | AU8: =sum(AP8:AT8) -> 205.88575 | AV8: =sumifs(accountingImpact,assetLookUp,$A8,financialMonth,AV$2,financialYear,AV$1,transactionType,"Revaluation") -> 0 | AW8: =sumifs(accountingImpact,assetLookUp,$A8,financialMonth,AV$2,financialYear,AV$1,transactionType,"Acquisition") -> 0 | AX8: =sumifs(accountingImpact,assetLookUp,$A8,financialMonth,AV$2,financialYear,AV$1,transactionType,"Disposal") -> 0 | AY8: {=-sum(AU8:AX8)*index(depnRateAcc,match($A8,assetLookUp,0),)} -> -61.765725 | AZ8: =sum(AU8:AY8) -> 144.12002 | BA8: =sumifs(accountingImpact,assetLookUp,$A8,financialMonth,BA$2,financialYear,BA$1,transactionType,"Revaluation") -> 0 | BB8: =sumifs(accountingImpact,assetLookUp,$A8,financialMonth,BA$2,financialYear,BA$1,transactionType,"Acquisition") -> 0 | BC8: =sumifs(accountingImpact,assetLookUp,$A8,financialMonth,BA$2,financialYear,BA$1,transactionType,"Disposal") -> 0 | BD8: {=-sum(AZ8:BC8)*index(depnRateAcc,match($A8,assetLookUp,0),)} -> -43.236007 | BE8: =sum(AZ8:BD8) -> 100.88402 | BF8: =sumifs(accountingImpact,assetLookUp,$A8,financialMonth,BF$2,financialYear,BF$1,transactionType,"Revaluation") -> 0 | BG8: =sumifs(accountingImpact,assetLookUp,$A8,financialMonth,BF$2,financialYear,BF$1,transactionType,"Acquisition") -> 0 | BH8: =sumifs(accountingImpact,assetLookUp,$A8,financialMonth,BF$2,financialYear,BF$1,transactionType,"Disposal") -> 0 | BI8: {=-sum(BE8:BH8)*index(depnRateAcc,match($A8,assetLookUp,0),)} -> -30.265205 | BJ8: {=index(assetClass,match($A8,assetLookUp,0))} -> Vehicles | BK8: =B8 -> 0 | BL8: =sumif($B$4:$BI$4,"Revalns",$B8:$BI8) -> 0 | BM8: =sumif($B$4:$BI$4,"Acquisitions",$B8:$BI8) -> 2500 | BN8: =sumif($B$4:$BI$4,"Disposals",$B8:$BI8) -> 0 | BO8: =sumif($B$4:$BI$4,"Depn",$B8:$BI8) -> -2429.3812 | BP8: =sum(BK8:BO8) -> 70.618812
A9: 00005 | B9: 0 | C9: =sumifs(accountingImpact,assetLookUp,$A9,financialMonth,C$2,financialYear,C$1,transactionType,"Revaluation") -> 0 | D9: =sumifs(accountingImpact,assetLookUp,$A9,financialMonth,C$2,financialYear,C$1,transactionType,"Acquisition") -> 0 | E9: =sumifs(accountingImpact,assetLookUp,$A9,financialMonth,C$2,financialYear,C$1,transactionType,"Disposal") -> 0 | F9: {=-sum(B9:E9)*index(depnRateAcc,match($A9,assetLookUp,0),)} -> 0 | G9: =sum(B9:F9) -> 0 | H9: =sumifs(accountingImpact,assetLookUp,$A9,financialMonth,H$2,financialYear,H$1,transactionType,"Revaluation") -> 0 | I9: =sumifs(accountingImpact,assetLookUp,$A9,financialMonth,H$2,financialYear,H$1,transactionType,"Acquisition") -> 0 | J9: =sumifs(accountingImpact,assetLookUp,$A9,financialMonth,H$2,financialYear,H$1,transactionType,"Disposal") -> 0 | K9: {=-sum(G9:J9)*index(depnRateAcc,match($A9,assetLookUp,0),)} -> 0 | L9: =sum(G9:K9) -> 0 | M9: =sumifs(accountingImpact,assetLookUp,$A9,financialMonth,M$2,financialYear,M$1,transactionType,"Revaluation") -> 0 | N9: =sumifs(accountingImpact,assetLookUp,$A9,financialMonth,M$2,financialYear,M$1,transactionType,"Acquisition") -> 0 | O9: =sumifs(accountingImpact,assetLookUp,$A9,financialMonth,M$2,financialYear,M$1,transactionType,"Disposal") -> 0 | P9: {=-sum(L9:O9)*index(depnRateAcc,match($A9,assetLookUp,0),)} -> 0 | Q9: =sum(L9:P9) -> 0 | R9: =sumifs(accountingImpact,assetLookUp,$A9,financialMonth,R$2,financialYear,R$1,transactionType,"Revaluation") -> 0 | S9: =sumifs(accountingImpact,assetLookUp,$A9,financialMonth,R$2,financialYear,R$1,transactionType,"Acquisition") -> 0 | T9: =sumifs(accountingImpact,assetLookUp,$A9,financialMonth,R$2,financialYear,R$1,transactionType,"Disposal") -> 0 | U9: {=-sum(Q9:T9)*index(depnRateAcc,match($A9,assetLookUp,0),)} -> 0 | V9: =sum(Q9:U9) -> 0 | W9: =sumifs(accountingImpact,assetLookUp,$A9,financialMonth,W$2,financialYear,W$1,transactionType,"Revaluation") -> 0 | X9: =sumifs(accountingImpact,assetLookUp,$A9,financialMonth,W$2,financialYear,W$1,transactionType,"Acquisition") -> 0 | Y9: =sumifs(accountingImpact,assetLookUp,$A9,financialMonth,W$2,financialYear,W$1,transactionType,"Disposal") -> 0 | Z9: {=-sum(V9:Y9)*index(depnRateAcc,match($A9,assetLookUp,0),)} -> 0 | AA9: =sum(V9:Z9) -> 0 | AB9: =sumifs(accountingImpact,assetLookUp,$A9,financialMonth,AB$2,financialYear,AB$1,transactionType,"Revaluation") -> 0 | AC9: =sumifs(accountingImpact,assetLookUp,$A9,financialMonth,AB$2,financialYear,AB$1,transactionType,"Acquisition") -> 0 | AD9: =sumifs(accountingImpact,assetLookUp,$A9,financialMonth,AB$2,financialYear,AB$1,transactionType,"Disposal") -> 0 | AE9: {=-sum(AA9:AD9)*index(depnRateAcc,match($A9,assetLookUp,0),)} -> 0 | AF9: =sum(AA9:AE9) -> 0 | AG9: =sumifs(accountingImpact,assetLookUp,$A9,financialMonth,AG$2,financialYear,AG$1,transactionType,"Revaluation") -> 0 | AH9: =sumifs(accountingImpact,assetLookUp,$A9,financialMonth,AG$2,financialYear,AG$1,transactionType,"Acquisition") -> 0 | AI9: =sumifs(accountingImpact,assetLookUp,$A9,financialMonth,AG$2,financialYear,AG$1,transactionType,"Disposal") -> 0 | AJ9: {=-sum(AF9:AI9)*index(depnRateAcc,match($A9,assetLookUp,0),)} -> 0 | AK9: =sum(AF9:AJ9) -> 0 | AL9: =sumifs(accountingImpact,assetLookUp,$A9,financialMonth,AL$2,financialYear,AL$1,transactionType,"Revaluation") -> 0 | AM9: =sumifs(accountingImpact,assetLookUp,$A9,financialMonth,AL$2,financialYear,AL$1,transactionType,"Acquisition") -> 0 | AN9: =sumifs(accountingImpact,assetLookUp,$A9,financialMonth,AL$2,financialYear,AL$1,transactionType,"Disposal") -> 0 | AO9: {=-sum(AK9:AN9)*index(depnRateAcc,match($A9,assetLookUp,0),)} -> 0 | AP9: =sum(AK9:AO9) -> 0 | AQ9: =sumifs(accountingImpact,assetLookUp,$A9,financialMonth,AQ$2,financialYear,AQ$1,transactionType,"Revaluation") -> 0 | AR9: =sumifs(accountingImpact,assetLookUp,$A9,financialMonth,AQ$2,financialYear,AQ$1,transactionType,"Acquisition") -> 0 | AS9: =sumifs(accountingImpact,assetLookUp,$A9,financialMonth,AQ$2,financialYear,AQ$1,transactionType,"Disposal") -> 0 | AT9: {=-sum(AP9:AS9)*index(depnRateAcc,match($A9,assetLookUp,0),)} -> 0 | AU9: =sum(AP9:AT9) -> 0 | AV9: =sumifs(accountingImpact,assetLookUp,$A9,financialMonth,AV$2,financialYear,AV$1,transactionType,"Revaluation") -> 0 | AW9: =sumifs(accountingImpact,assetLookUp,$A9,financialMonth,AV$2,financialYear,AV$1,transactionType,"Acquisition") -> 0 | AX9: =sumifs(accountingImpact,assetLookUp,$A9,financialMonth,AV$2,financialYear,AV$1,transactionType,"Disposal") -> 0 | AY9: {=-sum(AU9:AX9)*index(depnRateAcc,match($A9,assetLookUp,0),)} -> 0 | AZ9: =sum(AU9:AY9) -> 0 | BA9: =sumifs(accountingImpact,assetLookUp,$A9,financialMonth,BA$2,financialYear,BA$1,transactionType,"Revaluation") -> 0 | BB9: =sumifs(accountingImpact,assetLookUp,$A9,financialMonth,BA$2,financialYear,BA$1,transactionType,"Acquisition") -> 0 | BC9: =sumifs(accountingImpact,assetLookUp,$A9,financialMonth,BA$2,financialYear,BA$1,transactionType,"Disposal") -> 0 | BD9: {=-sum(AZ9:BC9)*index(depnRateAcc,match($A9,assetLookUp,0),)} -> 0 | BE9: =sum(AZ9:BD9) -> 0 | BF9: =sumifs(accountingImpact,assetLookUp,$A9,financialMonth,BF$2,financialYear,BF$1,transactionType,"Revaluation") -> 0 | BG9: =sumifs(accountingImpact,assetLookUp,$A9,financialMonth,BF$2,financialYear,BF$1,transactionType,"Acquisition") -> 0 | BH9: =sumifs(accountingImpact,assetLookUp,$A9,financialMonth,BF$2,financialYear,BF$1,transactionType,"Disposal") -> 0 | BI9: {=-sum(BE9:BH9)*index(depnRateAcc,match($A9,assetLookUp,0),)} -> 0 | BJ9: {=index(assetClass,match($A9,assetLookUp,0))} -> Computer software | BK9: =B9 -> 0 | BL9: =sumif($B$4:$BI$4,"Revalns",$B9:$BI9) -> 0 | BM9: =sumif($B$4:$BI$4,"Acquisitions",$B9:$BI9) -> 0 | BN9: =sumif($B$4:$BI$4,"Disposals",$B9:$BI9) -> 0 | BO9: =sumif($B$4:$BI$4,"Depn",$B9:$BI9) -> 0 | BP9: =sum(BK9:BO9) -> 0
A10: 00006 | B10: 0 | C10: =sumifs(accountingImpact,assetLookUp,$A10,financialMonth,C$2,financialYear,C$1,transactionType,"Revaluation") -> 0 | D10: =sumifs(accountingImpact,assetLookUp,$A10,financialMonth,C$2,financialYear,C$1,transactionType,"Acquisition") -> 0 | E10: =sumifs(accountingImpact,assetLookUp,$A10,financialMonth,C$2,financialYear,C$1,transactionType,"Disposal") -> 0 | F10: {=-sum(B10:E10)*index(depnRateAcc,match($A10,assetLookUp,0),)} -> 0 | G10: =sum(B10:F10) -> 0 | H10: =sumifs(accountingImpact,assetLookUp,$A10,financialMonth,H$2,financialYear,H$1,transactionType,"Revaluation") -> 0 | I10: =sumifs(accountingImpact,assetLookUp,$A10,financialMonth,H$2,financialYear,H$1,transactionType,"Acquisition") -> 0 | J10: =sumifs(accountingImpact,assetLookUp,$A10,financialMonth,H$2,financialYear,H$1,transactionType,"Disposal") -> 0 | K10: {=-sum(G10:J10)*index(depnRateAcc,match($A10,assetLookUp,0),)} -> 0 | L10: =sum(G10:K10) -> 0 | M10: =sumifs(accountingImpact,assetLookUp,$A10,financialMonth,M$2,financialYear,M$1,transactionType,"Revaluation") -> 0 | N10: =sumifs(accountingImpact,assetLookUp,$A10,financialMonth,M$2,financialYear,M$1,transactionType,"Acquisition") -> 0 | O10: =sumifs(accountingImpact,assetLookUp,$A10,financialMonth,M$2,financialYear,M$1,transactionType,"Disposal") -> 0 | P10: {=-sum(L10:O10)*index(depnRateAcc,match($A10,assetLookUp,0),)} -> 0 | Q10: =sum(L10:P10) -> 0 | R10: =sumifs(accountingImpact,assetLookUp,$A10,financialMonth,R$2,financialYear,R$1,transactionType,"Revaluation") -> 0 | S10: =sumifs(accountingImpact,assetLookUp,$A10,financialMonth,R$2,financialYear,R$1,transactionType,"Acquisition") -> 0 | T10: =sumifs(accountingImpact,assetLookUp,$A10,financialMonth,R$2,financialYear,R$1,transactionType,"Disposal") -> 0 | U10: {=-sum(Q10:T10)*index(depnRateAcc,match($A10,assetLookUp,0),)} -> 0 | V10: =sum(Q10:U10) -> 0 | W10: =sumifs(accountingImpact,assetLookUp,$A10,financialMonth,W$2,financialYear,W$1,transactionType,"Revaluation") -> 0 | X10: =sumifs(accountingImpact,assetLookUp,$A10,financialMonth,W$2,financialYear,W$1,transactionType,"Acquisition") -> 0 | Y10: =sumifs(accountingImpact,assetLookUp,$A10,financialMonth,W$2,financialYear,W$1,transactionType,"Disposal") -> 0 | Z10: {=-sum(V10:Y10)*index(depnRateAcc,match($A10,assetLookUp,0),)} -> 0 | AA10: =sum(V10:Z10) -> 0 | AB10: =sumifs(accountingImpact,assetLookUp,$A10,financialMonth,AB$2,financialYear,AB$1,transactionType,"Revaluation") -> 0 | AC10: =sumifs(accountingImpact,assetLookUp,$A10,financialMonth,AB$2,financialYear,AB$1,transactionType,"Acquisition") -> 0 | AD10: =sumifs(accountingImpact,assetLookUp,$A10,financialMonth,AB$2,financialYear,AB$1,transactionType,"Disposal") -> 0 | AE10: {=-sum(AA10:AD10)*index(depnRateAcc,match($A10,assetLookUp,0),)} -> 0 | AF10: =sum(AA10:AE10) -> 0 | AG10: =sumifs(accountingImpact,assetLookUp,$A10,financialMonth,AG$2,financialYear,AG$1,transactionType,"Revaluation") -> 0 | AH10: =sumifs(accountingImpact,assetLookUp,$A10,financialMonth,AG$2,financialYear,AG$1,transactionType,"Acquisition") -> 0 | AI10: =sumifs(accountingImpact,assetLookUp,$A10,financialMonth,AG$2,financialYear,AG$1,transactionType,"Disposal") -> 0 | AJ10: {=-sum(AF10:AI10)*index(depnRateAcc,match($A10,assetLookUp,0),)} -> 0 | AK10: =sum(AF10:AJ10) -> 0 | AL10: =sumifs(accountingImpact,assetLookUp,$A10,financialMonth,AL$2,financialYear,AL$1,transactionType,"Revaluation") -> 0 | AM10: =sumifs(accountingImpact,assetLookUp,$A10,financialMonth,AL$2,financialYear,AL$1,transactionType,"Acquisition") -> 0 | AN10: =sumifs(accountingImpact,assetLookUp,$A10,financialMonth,AL$2,financialYear,AL$1,transactionType,"Disposal") -> 0 | AO10: {=-sum(AK10:AN10)*index(depnRateAcc,match($A10,assetLookUp,0),)} -> 0 | AP10: =sum(AK10:AO10) -> 0 | AQ10: =sumifs(accountingImpact,assetLookUp,$A10,financialMonth,AQ$2,financialYear,AQ$1,transactionType,"Revaluation") -> 0 | AR10: =sumifs(accountingImpact,assetLookUp,$A10,financialMonth,AQ$2,financialYear,AQ$1,transactionType,"Acquisition") -> 0 | AS10: =sumifs(accountingImpact,assetLookUp,$A10,financialMonth,AQ$2,financialYear,AQ$1,transactionType,"Disposal") -> 0 | AT10: {=-sum(AP10:AS10)*index(depnRateAcc,match($A10,assetLookUp,0),)} -> 0 | AU10: =sum(AP10:AT10) -> 0 | AV10: =sumifs(accountingImpact,assetLookUp,$A10,financialMonth,AV$2,financialYear,AV$1,transactionType,"Revaluation") -> 0 | AW10: =sumifs(accountingImpact,assetLookUp,$A10,financialMonth,AV$2,financialYear,AV$1,transactionType,"Acquisition") -> 800 | AX10: =sumifs(accountingImpact,assetLookUp,$A10,financialMonth,AV$2,financialYear,AV$1,transactionType,"Disposal") -> 0 | AY10: {=-sum(AU10:AX10)*index(depnRateAcc,match($A10,assetLookUp,0),)} -> -400 | AZ10: =sum(AU10:AY10) -> 400 | BA10: =sumifs(accountingImpact,assetLookUp,$A10,financialMonth,BA$2,financialYear,BA$1,transactionType,"Revaluation") -> 0 | BB10: =sumifs(accountingImpact,assetLookUp,$A10,financialMonth,BA$2,financialYear,BA$1,transactionType,"Acquisition") -> 0 | BC10: =sumifs(accountingImpact,assetLookUp,$A10,financialMonth,BA$2,financialYear,BA$1,transactionType,"Disposal") -> 0 | BD10: {=-sum(AZ10:BC10)*index(depnRateAcc,match($A10,assetLookUp,0),)} -> -200 | BE10: =sum(AZ10:BD10) -> 200 | BF10: =sumifs(accountingImpact,assetLookUp,$A10,financialMonth,BF$2,financialYear,BF$1,transactionType,"Revaluation") -> 0 | BG10: =sumifs(accountingImpact,assetLookUp,$A10,financialMonth,BF$2,financialYear,BF$1,transactionType,"Acquisition") -> 0 | BH10: =sumifs(accountingImpact,assetLookUp,$A10,financialMonth,BF$2,financialYear,BF$1,transactionType,"Disposal") -> 0 | BI10: {=-sum(BE10:BH10)*index(depnRateAcc,match($A10,assetLookUp,0),)} -> -100 | BJ10: {=index(assetClass,match($A10,assetLookUp,0))} -> Plant and equipment | BK10: =B10 -> 0 | BL10: =sumif($B$4:$BI$4,"Revalns",$B10:$BI10) -> 0 | BM10: =sumif($B$4:$BI$4,"Acquisitions",$B10:$BI10) -> 800 | BN10: =sumif($B$4:$BI$4,"Disposals",$B10:$BI10) -> 0 | BO10: =sumif($B$4:$BI$4,"Depn",$B10:$BI10) -> -700 | BP10: =sum(BK10:BO10) -> 100
A13: Year | B13: 2024 | C13: 2024 | D13: 2024 | E13: 2024 | F13: 2024 | G13: 2024 | H13: 2024 | I13: 2024 | J13: 2024 | K13: 2024 | L13: 2024 | M13: 2024 | N13: 2024 | O13: 2024 | P13: 2024 | Q13: 2024 | R13: 2024 | S13: 2024 | T13: 2024 | U13: 2024 | V13: 2024 | W13: 2024 | X13: 2024 | Y13: 2024 | Z13: 2024 | AA13: 2024 | AB13: 2024 | AC13: 2024 | AD13: 2024 | AE13: 2024 | AF13: 2024 | AG13: 2024 | AH13: 2024 | AI13: 2024 | AJ13: 2024 | AK13: 2024 | AL13: 2024 | AM13: 2024 | AN13: 2024 | AO13: 2024 | AP13: 2024 | AQ13: 2024 | AR13: 2024 | AS13: 2024 | AT13: 2024 | AU13: 2024 | AV13: 2024 | AW13: 2024 | AX13: 2024 | AY13: 2024 | AZ13: 2024 | BA13: 2024 | BB13: 2024 | BC13: 2024 | BD13: 2024 | BE13: 2024 | BF13: 2024 | BG13: 2024 | BH13: 2024 | BI13: 2024
A14: Month | B14: 1 | C14: 1 | D14: 1 | E14: 1 | F14: 1 | G14: 2 | H14: 2 | I14: 2 | J14: 2 | K14: 2 | L14: 3 | M14: 3 | N14: 3 | O14: 3 | P14: 3 | Q14: 4 | R14: 4 | S14: 4 | T14: 4 | U14: 4 | V14: 5 | W14: 5 | X14: 5 | Y14: 5 | Z14: 5 | AA14: 6 | AB14: 6 | AC14: 6 | AD14: 6 | AE14: 6 | AF14: 7 | AG14: 7 | AH14: 7 | AI14: 7 | AJ14: 7 | AK14: 8 | AL14: 8 | AM14: 8 | AN14: 8 | AO14: 8 | AP14: 9 | AQ14: 9 | AR14: 9 | AS14: 9 | AT14: 9 | AU14: 10 | AV14: 10 | AW14: 10 | AX14: 10 | AY14: 10 | AZ14: 11 | BA14: 11 | BB14: 11 | BC14: 11 | BD14: 11 | BE14: 12 | BF14: 12 | BG14: 12 | BH14: 12 | BI14: 12 | BK14: Note - classificaiton at close would by default be the opening
A15: Assets | B15: Month One | G15: Month Two | L15: Month Three | Q15: Month Four | V15: Month Five | AA15: Month Six | AF15: Month Seven | AK15: Month Eight | AP15: Month Nine | AU15: Month Ten | AZ15: Month Eleven | BE15: Month Twelve | BJ15: Tax classification at close | BK15: But if there has been a reclassification in the year, we would want to take that as an override
B16: Opening value | C16: Revalns | D16: Acquisitions | E16: Disposals | F16: Depn | G16: Opening value | H16: Revalns | I16: Acquisitions | J16: Disposals | K16: Depn | L16: Opening value | M16: Revalns | N16: Acquisitions | O16: Disposals | P16: Depn | Q16: Opening value | R16: Revalns | S16: Acquisitions | T16: Disposals | U16: Depn | V16: Opening value | W16: Revalns | X16: Acquisitions | Y16: Disposals | Z16: Depn | AA16: Opening value | AB16: Revalns | AC16: Acquisitions | AD16: Disposals | AE16: Depn | AF16: Opening value | AG16: Revalns | AH16: Acquisitions | AI16: Disposals | AJ16: Depn | AK16: Opening value | AL16: Revalns | AM16: Acquisitions | AN16: Disposals | AO16: Depn | AP16: Opening value | AQ16: Revalns | AR16: Acquisitions | AS16: Disposals | AT16: Depn | AU16: Opening value | AV16: Revalns | AW16: Acquisitions | AX16: Disposals | AY16: Depn | AZ16: Opening value | BA16: Revalns | BB16: Acquisitions | BC16: Disposals | BD16: Depn | BE16: Opening value | BF16: Revalns | BG16: Acquisitions | BH16: Disposals | BI16: Depn | BK16: Open | BL16: Total revals | BM16: Total additions | BN16: Total disposals | BO16: Total depn | BP16: Close
A17: 00001 | B17: 0 | C17: =sumifs(taxImpact,assetLookUp,$A17,financialMonth,C$2,financialYear,C$1,transactionType,"Revaluation") -> 0 | D17: =sumifs(taxImpact,assetLookUp,$A17,financialMonth,C$2,financialYear,C$1,transactionType,"Acquisition") -> 5000000 | E17: =sumifs(taxImpact,assetLookUp,$A17,financialMonth,C$2,financialYear,C$1,transactionType,"Disposal") -> 0 | F17: {=-sum(B17:E17)*index(depnRateTax,match($A17,assetLookUp,0),)} -> 0 | G17: =sum(B17:F17) -> 5000000 | H17: =sumifs(taxImpact,assetLookUp,$A17,financialMonth,H$2,financialYear,H$1,transactionType,"Revaluation") -> 0 | I17: =sumifs(taxImpact,assetLookUp,$A17,financialMonth,H$2,financialYear,H$1,transactionType,"Acquisition") -> 0 | J17: =sumifs(taxImpact,assetLookUp,$A17,financialMonth,H$2,financialYear,H$1,transactionType,"Disposal") -> 0 | K17: {=-sum(G17:J17)*index(depnRateTax,match($A17,assetLookUp,0),)} -> 0 | L17: =sum(G17:K17) -> 5000000 | M17: =sumifs(taxImpact,assetLookUp,$A17,financialMonth,M$2,financialYear,M$1,transactionType,"Revaluation") -> 0 | N17: =sumifs(taxImpact,assetLookUp,$A17,financialMonth,M$2,financialYear,M$1,transactionType,"Acquisition") -> 0 | O17: =sumifs(taxImpact,assetLookUp,$A17,financialMonth,M$2,financialYear,M$1,transactionType,"Disposal") -> 0 | P17: {=-sum(L17:O17)*index(depnRateTax,match($A17,assetLookUp,0),)} -> 0 | Q17: =sum(L17:P17) -> 5000000 | R17: =sumifs(taxImpact,assetLookUp,$A17,financialMonth,R$2,financialYear,R$1,transactionType,"Revaluation") -> 0 | S17: =sumifs(taxImpact,assetLookUp,$A17,financialMonth,R$2,financialYear,R$1,transactionType,"Acquisition") -> 0 | T17: =sumifs(taxImpact,assetLookUp,$A17,financialMonth,R$2,financialYear,R$1,transactionType,"Disposal") -> 0 | U17: {=-sum(Q17:T17)*index(depnRateTax,match($A17,assetLookUp,0),)} -> 0 | V17: =sum(Q17:U17) -> 5000000 | W17: =sumifs(taxImpact,assetLookUp,$A17,financialMonth,W$2,financialYear,W$1,transactionType,"Revaluation") -> 0 | X17: =sumifs(taxImpact,assetLookUp,$A17,financialMonth,W$2,financialYear,W$1,transactionType,"Acquisition") -> 0 | Y17: =sumifs(taxImpact,assetLookUp,$A17,financialMonth,W$2,financialYear,W$1,transactionType,"Disposal") -> 0 | Z17: {=-sum(V17:Y17)*index(depnRateTax,match($A17,assetLookUp,0),)} -> 0 | AA17: =sum(V17:Z17) -> 5000000 | AB17: =sumifs(taxImpact,assetLookUp,$A17,financialMonth,AB$2,financialYear,AB$1,transactionType,"Revaluation") -> 0 | AC17: =sumifs(taxImpact,assetLookUp,$A17,financialMonth,AB$2,financialYear,AB$1,transactionType,"Acquisition") -> 0 | AD17: =sumifs(taxImpact,assetLookUp,$A17,financialMonth,AB$2,financialYear,AB$1,transactionType,"Disposal") -> 0 | AE17: {=-sum(AA17:AD17)*index(depnRateTax,match($A17,assetLookUp,0),)} -> 0 | AF17: =sum(AA17:AE17) -> 5000000 | AG17: =sumifs(taxImpact,assetLookUp,$A17,financialMonth,AG$2,financialYear,AG$1,transactionType,"Revaluation") -> 0 | AH17: =sumifs(taxImpact,assetLookUp,$A17,financialMonth,AG$2,financialYear,AG$1,transactionType,"Acquisition") -> 0 | AI17: =sumifs(taxImpact,assetLookUp,$A17,financialMonth,AG$2,financialYear,AG$1,transactionType,"Disposal") -> 0 | AJ17: {=-sum(AF17:AI17)*index(depnRateTax,match($A17,assetLookUp,0),)} -> 0 | AK17: =sum(AF17:AJ17) -> 5000000 | AL17: =sumifs(taxImpact,assetLookUp,$A17,financialMonth,AL$2,financialYear,AL$1,transactionType,"Revaluation") -> 0 | AM17: =sumifs(taxImpact,assetLookUp,$A17,financialMonth,AL$2,financialYear,AL$1,transactionType,"Acquisition") -> 0 | AN17: =sumifs(taxImpact,assetLookUp,$A17,financialMonth,AL$2,financialYear,AL$1,transactionType,"Disposal") -> 0 | AO17: {=-sum(AK17:AN17)*index(depnRateTax,match($A17,assetLookUp,0),)} -> 0 | AP17: =sum(AK17:AO17) -> 5000000 | AQ17: =sumifs(taxImpact,assetLookUp,$A17,financialMonth,AQ$2,financialYear,AQ$1,transactionType,"Revaluation") -> 0 | AR17: =sumifs(taxImpact,assetLookUp,$A17,financialMonth,AQ$2,financialYear,AQ$1,transactionType,"Acquisition") -> 0 | AS17: =sumifs(taxImpact,assetLookUp,$A17,financialMonth,AQ$2,financialYear,AQ$1,transactionType,"Disposal") -> 0 | AT17: {=-sum(AP17:AS17)*index(depnRateTax,match($A17,assetLookUp,0),)} -> 0 | AU17: =sum(AP17:AT17) -> 5000000 | AV17: =sumifs(taxImpact,assetLookUp,$A17,financialMonth,AV$2,financialYear,AV$1,transactionType,"Revaluation") -> 0 | AW17: =sumifs(taxImpact,assetLookUp,$A17,financialMonth,AV$2,financialYear,AV$1,transactionType,"Acquisition") -> 0 | AX17: =sumifs(taxImpact,assetLookUp,$A17,financialMonth,AV$2,financialYear,AV$1,transactionType,"Disposal") -> 0 | AY17: {=-sum(AU17:AX17)*index(depnRateTax,match($A17,assetLookUp,0),)} -> 0 | AZ17: =sum(AU17:AY17) -> 5000000 | BA17: =sumifs(taxImpact,assetLookUp,$A17,financialMonth,BA$2,financialYear,BA$1,transactionType,"Revaluation") -> 0 | BB17: =sumifs(taxImpact,assetLookUp,$A17,financialMonth,BA$2,financialYear,BA$1,transactionType,"Acquisition") -> 0 | BC17: =sumifs(taxImpact,assetLookUp,$A17,financialMonth,BA$2,financialYear,BA$1,transactionType,"Disposal") -> 0 | BD17: {=-sum(AZ17:BC17)*index(depnRateTax,match($A17,assetLookUp,0),)} -> 0 | BE17: =sum(AZ17:BD17) -> 5000000 | BF17: =sumifs(taxImpact,assetLookUp,$A17,financialMonth,BF$2,financialYear,BF$1,transactionType,"Revaluation") -> 0 | BG17: =sumifs(taxImpact,assetLookUp,$A17,financialMonth,BF$2,financialYear,BF$1,transactionType,"Acquisition") -> 0 | BH17: =sumifs(taxImpact,assetLookUp,$A17,financialMonth,BF$2,financialYear,BF$1,transactionType,"Disposal") -> 0 | BI17: {=-sum(BE17:BH17)*index(depnRateTax,match($A17,assetLookUp,0),)} -> 0 | BJ17: {=index(assetClass,match($A17,assetLookUp,0))} -> Land (freehold) | BK17: =B17 -> 0 | BL17: =sumif($B$4:$BI$4,"Revalns",$B17:$BI17) -> 0 | BM17: =sumif($B$4:$BI$4,"Acquisitions",$B17:$BI17) -> 5000000 | BN17: =sumif($B$4:$BI$4,"Disposals",$B17:$BI17) -> 0 | BO17: =sumif($B$4:$BI$4,"Depn",$B17:$BI17) -> 0 | BP17: =sum(BK17:BO17) -> 5000000
